<?xml version="1.0" encoding="UTF-8"?>
<!-- Generated by org.testng.reporters.JUnitReportReporter -->
<testsuite hostname="DESKTOP-TU76DCC" name="SystemMailTracking.testcases.SessionSuite.ContinueToPaymentTest" tests="1" failures="0" timestamp="30 May 2018 15:51:05 GMT" time="92.062" errors="1">
  <testcase name="ContinueToPayment" time="92.062" classname="SystemMailTracking.testcases.SessionSuite.ContinueToPaymentTest">
    <error type="java.lang.reflect.InvocationTargetException">
      <![CDATA[java.lang.reflect.InvocationTargetException
	at sun.reflect.NativeMethodAccessorImpl.invoke0(Native Method)
	at sun.reflect.NativeMethodAccessorImpl.invoke(Unknown Source)
	at sun.reflect.DelegatingMethodAccessorImpl.invoke(Unknown Source)
	at java.lang.reflect.Method.invoke(Unknown Source)
	at SystemMailTracking.driver.DriverScript.executeKeywords(DriverScript.java:49)
	at SystemMailTracking.testcases.SessionSuite.ContinueToPaymentTest.ContinueToPayment(ContinueToPaymentTest.java:27)
	at sun.reflect.NativeMethodAccessorImpl.invoke0(Native Method)
	at sun.reflect.NativeMethodAccessorImpl.invoke(Unknown Source)
	at sun.reflect.DelegatingMethodAccessorImpl.invoke(Unknown Source)
	at java.lang.reflect.Method.invoke(Unknown Source)
	at org.testng.internal.MethodInvocationHelper.invokeMethod(MethodInvocationHelper.java:85)
	at org.testng.internal.Invoker.invokeMethod(Invoker.java:639)
	at org.testng.internal.Invoker.invokeTestMethod(Invoker.java:821)
	at org.testng.internal.Invoker.invokeTestMethods(Invoker.java:1131)
	at org.testng.internal.TestMethodWorker.invokeTestMethods(TestMethodWorker.java:124)
	at org.testng.internal.TestMethodWorker.run(TestMethodWorker.java:108)
	at org.testng.TestRunner.privateRun(TestRunner.java:773)
	at org.testng.TestRunner.run(TestRunner.java:623)
	at org.testng.SuiteRunner.runTest(SuiteRunner.java:357)
	at org.testng.SuiteRunner.runSequentially(SuiteRunner.java:352)
	at org.testng.SuiteRunner.privateRun(SuiteRunner.java:310)
	at org.testng.SuiteRunner.run(SuiteRunner.java:259)
	at org.testng.SuiteRunnerWorker.runSuite(SuiteRunnerWorker.java:52)
	at org.testng.SuiteRunnerWorker.run(SuiteRunnerWorker.java:86)
	at org.testng.TestNG.runSuitesSequentially(TestNG.java:1185)
	at org.testng.TestNG.runSuitesSequentially(TestNG.java:1181)
	at org.testng.TestNG.runSuitesLocally(TestNG.java:1110)
	at org.testng.TestNG.run(TestNG.java:1018)
	at org.testng.remote.AbstractRemoteTestNG.run(AbstractRemoteTestNG.java:114)
	at org.testng.remote.RemoteTestNG.initAndRun(RemoteTestNG.java:251)
	at org.testng.remote.RemoteTestNG.main(RemoteTestNG.java:77)
Caused by: java.lang.AssertionError: The following asserts failed:
	Object Not Found MailinatorNewAccountwithPaymentMail_xpath	Object Not Found MailinatorNewAccountwithPaymentMail_xpath, 
	Failed to get the email confirmation for newly created account with payment	Failed to get the email confirmation for newly created account with payment
	at org.testng.asserts.SoftAssert.assertAll(SoftAssert.java:48)
	at SystemMailTracking.keywords.GenericKeywords.reportFailure(GenericKeywords.java:362)
	at SystemMailTracking.keywords.AppKeywords.VerifyEmailFromInboxNewAccountwithPayment(AppKeywords.java:232)
	... 31 more
]]>
    </error>
  </testcase> <!-- ContinueToPayment -->
</testsuite> <!-- SystemMailTracking.testcases.SessionSuite.ContinueToPaymentTest -->
